[2022-05-20 14:20:07,401] {taskinstance.py:1159} INFO - Dependencies all met for <TaskInstance: dag_may_20_2022.choose_best_model scheduled__2022-05-19T00:00:00+00:00 [queued]>
[2022-05-20 14:20:07,414] {taskinstance.py:1159} INFO - Dependencies all met for <TaskInstance: dag_may_20_2022.choose_best_model scheduled__2022-05-19T00:00:00+00:00 [queued]>
[2022-05-20 14:20:07,414] {taskinstance.py:1356} INFO - 
--------------------------------------------------------------------------------
[2022-05-20 14:20:07,415] {taskinstance.py:1357} INFO - Starting attempt 1 of 1
[2022-05-20 14:20:07,415] {taskinstance.py:1358} INFO - 
--------------------------------------------------------------------------------
[2022-05-20 14:20:07,431] {taskinstance.py:1377} INFO - Executing <Task(BranchPythonOperator): choose_best_model> on 2022-05-19 00:00:00+00:00
[2022-05-20 14:20:07,435] {standard_task_runner.py:52} INFO - Started process 309 to run task
[2022-05-20 14:20:07,439] {standard_task_runner.py:79} INFO - Running: ['***', 'tasks', 'run', 'dag_may_20_2022', 'choose_best_model', 'scheduled__2022-05-19T00:00:00+00:00', '--job-id', '82', '--raw', '--subdir', 'DAGS_FOLDER/dags.py', '--cfg-path', '/tmp/tmpe4w51hid', '--error-file', '/tmp/tmpb7nkxcyj']
[2022-05-20 14:20:07,440] {standard_task_runner.py:80} INFO - Job 82: Subtask choose_best_model
[2022-05-20 14:20:07,506] {task_command.py:369} INFO - Running <TaskInstance: dag_may_20_2022.choose_best_model scheduled__2022-05-19T00:00:00+00:00 [running]> on host 9764520d92aa
[2022-05-20 14:20:07,590] {taskinstance.py:1571} INFO - Exporting the following env vars:
AIRFLOW_CTX_DAG_OWNER=***
AIRFLOW_CTX_DAG_ID=dag_may_20_2022
AIRFLOW_CTX_TASK_ID=choose_best_model
AIRFLOW_CTX_EXECUTION_DATE=2022-05-19T00:00:00+00:00
AIRFLOW_CTX_TRY_NUMBER=1
AIRFLOW_CTX_DAG_RUN_ID=scheduled__2022-05-19T00:00:00+00:00
[2022-05-20 14:20:07,605] {taskinstance.py:1889} ERROR - Task failed with exception
Traceback (most recent call last):
  File "/home/airflow/.local/lib/python3.7/site-packages/airflow/operators/python.py", line 207, in execute
    branch = super().execute(context)
  File "/home/airflow/.local/lib/python3.7/site-packages/airflow/operators/python.py", line 171, in execute
    return_value = self.execute_callable()
  File "/home/airflow/.local/lib/python3.7/site-packages/airflow/operators/python.py", line 189, in execute_callable
    return self.python_callable(*self.op_args, **self.op_kwargs)
  File "/opt/airflow/dags/dags.py", line 16, in choose_best_ml_model
    best_accuracy =  max(accuracies)
ValueError: max() arg is an empty sequence
[2022-05-20 14:20:07,619] {taskinstance.py:1400} INFO - Marking task as FAILED. dag_id=dag_may_20_2022, task_id=choose_best_model, execution_date=20220519T000000, start_date=20220520T142007, end_date=20220520T142007
[2022-05-20 14:20:07,633] {standard_task_runner.py:97} ERROR - Failed to execute job 82 for task choose_best_model (max() arg is an empty sequence; 309)
[2022-05-20 14:20:07,652] {local_task_job.py:156} INFO - Task exited with return code 1
[2022-05-20 14:20:07,711] {local_task_job.py:273} INFO - 0 downstream tasks scheduled from follow-on schedule check
