[2022-05-20 14:39:48,934] {taskinstance.py:1159} INFO - Dependencies all met for <TaskInstance: interchange_dag.inaccurate manual__2022-05-20T14:39:47.471240+00:00 [queued]>
[2022-05-20 14:39:48,943] {taskinstance.py:1159} INFO - Dependencies all met for <TaskInstance: interchange_dag.inaccurate manual__2022-05-20T14:39:47.471240+00:00 [queued]>
[2022-05-20 14:39:48,944] {taskinstance.py:1356} INFO - 
--------------------------------------------------------------------------------
[2022-05-20 14:39:48,944] {taskinstance.py:1357} INFO - Starting attempt 1 of 1
[2022-05-20 14:39:48,945] {taskinstance.py:1358} INFO - 
--------------------------------------------------------------------------------
[2022-05-20 14:39:48,959] {taskinstance.py:1377} INFO - Executing <Task(BashOperator): inaccurate> on 2022-05-20 14:39:47.471240+00:00
[2022-05-20 14:39:48,964] {standard_task_runner.py:52} INFO - Started process 352 to run task
[2022-05-20 14:39:48,971] {standard_task_runner.py:79} INFO - Running: ['***', 'tasks', 'run', 'interchange_dag', 'inaccurate', 'manual__2022-05-20T14:39:47.471240+00:00', '--job-id', '89', '--raw', '--subdir', 'DAGS_FOLDER/interchange_dag.py', '--cfg-path', '/tmp/tmpby8bky6q', '--error-file', '/tmp/tmpgn3g2y38']
[2022-05-20 14:39:48,972] {standard_task_runner.py:80} INFO - Job 89: Subtask inaccurate
[2022-05-20 14:39:49,026] {task_command.py:369} INFO - Running <TaskInstance: interchange_dag.inaccurate manual__2022-05-20T14:39:47.471240+00:00 [running]> on host 421ba04fc7aa
[2022-05-20 14:39:49,094] {taskinstance.py:1571} INFO - Exporting the following env vars:
AIRFLOW_CTX_DAG_OWNER=***
AIRFLOW_CTX_DAG_ID=interchange_dag
AIRFLOW_CTX_TASK_ID=inaccurate
AIRFLOW_CTX_EXECUTION_DATE=2022-05-20T14:39:47.471240+00:00
AIRFLOW_CTX_TRY_NUMBER=1
AIRFLOW_CTX_DAG_RUN_ID=manual__2022-05-20T14:39:47.471240+00:00
[2022-05-20 14:39:49,096] {subprocess.py:62} INFO - Tmp dir root location: 
 /tmp
[2022-05-20 14:39:49,097] {subprocess.py:74} INFO - Running command: ['bash', '-c', 'docker run -ti interchange-python-docker']
[2022-05-20 14:39:49,110] {subprocess.py:85} INFO - Output:
[2022-05-20 14:39:49,112] {subprocess.py:92} INFO - bash: line 1: docker: command not found
[2022-05-20 14:39:49,112] {subprocess.py:96} INFO - Command exited with return code 127
[2022-05-20 14:39:49,128] {taskinstance.py:1889} ERROR - Task failed with exception
Traceback (most recent call last):
  File "/home/airflow/.local/lib/python3.7/site-packages/airflow/operators/bash.py", line 195, in execute
    f'Bash command failed. The command returned a non-zero exit code {result.exit_code}.'
airflow.exceptions.AirflowException: Bash command failed. The command returned a non-zero exit code 127.
[2022-05-20 14:39:49,131] {taskinstance.py:1400} INFO - Marking task as FAILED. dag_id=interchange_dag, task_id=inaccurate, execution_date=20220520T143947, start_date=20220520T143948, end_date=20220520T143949
[2022-05-20 14:39:49,142] {standard_task_runner.py:97} ERROR - Failed to execute job 89 for task inaccurate (Bash command failed. The command returned a non-zero exit code 127.; 352)
[2022-05-20 14:39:49,183] {local_task_job.py:156} INFO - Task exited with return code 1
[2022-05-20 14:39:49,216] {local_task_job.py:273} INFO - 0 downstream tasks scheduled from follow-on schedule check
